Workbook

Sheet Metadata

Sheet 1. Pop
B2: Table 1. Populations in New Mexico river basins, 2020.
B3: River Basin | C3: Category | D3: Population | E3: % Population
B4: Arkansas-White-Red | C4: Public Water Supply | D4: 27418 | E4: 0.012948154
B5: Arkansas-White-Red | C5: Self-Supplied Domestic | D5: 4089 | E5: 0.0019310307
C6: River Basin Totals | D6: 31507 | E6: 0.014879184
B8: Lower Colorado | C8: Public Water Supply | D8: 29693 | E8: 0.014022523
B9: Lower Colorado | C9: Self-Supplied Domestic | D9: 35844 | E9: 0.016927333
C10: River Basin Totals | D10: 65537 | E10: 0.030949856
B12: Pecos | C12: Public Water Supply | D12: 170661 | E12: 0.080594676
B13: Pecos | C13: Self-Supplied Domestic | D13: 23343 | E13: 0.011023734
C14: River Basin Totals | D14: 194004 | E14: 0.091618411
B16: Rio Grande | C16: Public Water Supply | D16: 1354359 | E16: 0.63959619
B17: Rio Grande | C17: Self-Supplied Domestic | D17: 209782 | E17: 0.099069573
C18: River Basin Totals | D18: 1564141 | E18: 0.73866576
B20: Texas Gulf | C20: Public Water Supply | D20: 116329 | E20: 0.054936383
B21: Texas Gulf | C21: Self-Supplied Domestic | D21: 17126 | E21: 0.0080877554
C22: River Basin Totals | D22: 133455 | E22: 0.063024139
B24: Upper Colorado | C24: Public Water Supply | D24: 108216 | E24: 0.051105018
B25: Upper Colorado | C25: Self-Supplied Domestic | D25: 20662 | E25: 0.0097576318
C26: River Basin Totals | D26: 128878 | E26: 0.06086265
B28: New Mexico | C28: Public Water Supply | D28: 1806676 | E28: 0.85320294
B29: New Mexico | C29: Self-Supplied Domestic | D29: 310846 | E29: 0.14679706
C30: State Totals | D30: 2117522 | E30: 1

Sheet 2. StateWith
B2: Table 2. Summary of withdrawals (acre-feet) in New Mexico, 2020.
B3: Category | C3: WSW | D3: WGW | E3: TW
B4: Public Water Supply | C4: 70332.799 | D4: 229470.35 | E4: 299803.15
B5: Domestic (self-supplied) | C5: 0 | D5: 30151.04 | E5: 30151.04
B6: Irrigated Agriculture | C6: 1467442 | D6: 1499256 | E6: 2966697
B7: Livestock (self-supplied) | C7: 3147 | D7: 35371 | E7: 38519
B8: Commercial (self-supplied) | C8: 26100.91 | D8: 30525.849 | E8: 56626.76
B9: Industrial (self-supplied) | C9: 0 | D9: 8586.103 | E9: 8586.103
B10: Mining (self-supplied) | C10: 366.67085 | D10: 56385.354 | E10: 56752.025
B11: Power (self-supplied) | C11: 32473.99 | D11: 32945.854 | E11: 65419.844
B12: Reservoir Evaporation | C12: 282522 | D12: 0 | E12: 282522
B13: State Totals | C13: =SUM(C4:C12) -> 1882385.4 | D13: =SUM(D4:D12) -> 1922691.6 | E13: =SUM(E4:E12) -> 3805076.9
B16: Key: WSW = withdrawal surface water; WGW = withdrawal groundwater; TW = total withdrawal.

Sheet 3. Category%
B2: Table 3. Withdrawals by category as a percent of state totals in New Mexico, 2020.
B3: Surface water and groundwater component of each category.
B4: Category | C4: % of State Withdrawal | E4: % WSW | F4: % WGW
B5: Public Water Supply | C5: =('2. StateWith'!E4/'2. StateWith'!E$13)*100 -> 7.87903 | E5: =('2. StateWith'!C4/'2. StateWith'!$E4)*100 -> 23.459659 | F5: =('2. StateWith'!D4/'2. StateWith'!$E4)*100 -> 76.540341
B6: Domestic (self-supplied) | C6: =('2. StateWith'!E5/'2. StateWith'!E$13)*100 -> 0.79238976 | E6: =('2. StateWith'!C5/'2. StateWith'!$E5)*100 -> 0 | F6: =('2. StateWith'!D5/'2. StateWith'!$E5)*100 -> 100
B7: Irrigated Agriculture | C7: =('2. StateWith'!E6/'2. StateWith'!E$13)*100 -> 77.966807 | E7: =('2. StateWith'!C6/'2. StateWith'!$E6)*100 -> 49.463831 | F7: =('2. StateWith'!D6/'2. StateWith'!$E6)*100 -> 50.536202
B8: Livestock (self-supplied) | C8: =('2. StateWith'!E7/'2. StateWith'!E$13)*100 -> 1.0123054 | E8: =('2. StateWith'!C7/'2. StateWith'!$E7)*100 -> 8.169994 | F8: =('2. StateWith'!D7/'2. StateWith'!$E7)*100 -> 91.82741
B9: Commercial (self-supplied) | C9: =('2. StateWith'!E8/'2. StateWith'!E$13)*100 -> 1.4881896 | E9: =('2. StateWith'!C8/'2. StateWith'!$E8)*100 -> 46.09289 | F9: =('2. StateWith'!D8/'2. StateWith'!$E8)*100 -> 53.90711
B10: Industrial (self-supplied) | C10: =('2. StateWith'!E9/'2. StateWith'!E$13)*100 -> 0.22564861 | E10: =('2. StateWith'!C9/'2. StateWith'!$E9)*100 -> 0 | F10: =('2. StateWith'!D9/'2. StateWith'!$E9)*100 -> 100
B11: Mining (self-supplied) | C11: =('2. StateWith'!E10/'2. StateWith'!E$13)*100 -> 1.4914817 | E11: =('2. StateWith'!C10/'2. StateWith'!$E10)*100 -> 0.64609297 | F11: =('2. StateWith'!D10/'2. StateWith'!$E10)*100 -> 99.353907
B12: Power (self-supplied) | C12: =('2. StateWith'!E11/'2. StateWith'!E$13)*100 -> 1.7192778 | E12: =('2. StateWith'!C11/'2. StateWith'!$E11)*100 -> 49.639357 | F12: =('2. StateWith'!D11/'2. StateWith'!$E11)*100 -> 50.360643
B13: Reservoir Evaporation | C13: =('2. StateWith'!E12/'2. StateWith'!E$13)*100 -> 7.4248696 | E13: =('2. StateWith'!C12/'2. StateWith'!$E12)*100 -> 100 | F13: =('2. StateWith'!D12/'2. StateWith'!$E12)*100 -> 0
B14: State Totals | C14: =('2. StateWith'!E13/'2. StateWith'!E$13)*100 -> 100 | E14: =('2. StateWith'!C13/'2. StateWith'!$E13)*100 -> 49.470363 | F14: =('2. StateWith'!D13/'2. StateWith'!$E13)*100 -> 50.529637
B17: Key: WSW = withdrawal surface water; WGW = withdrawal groundwater.

Sheet 4. %Measured
B2: Table 4. Percent of withdrawals measured in each water use category in New Mexico, 2020.
B3: Category | C3: MSW | D3: MGW | E3: MTW
B4: Public Water Supply | C4: 95 | D4: 98 | E4: 97
B5: Domestic (self-supplied) | C5: 0 | D5: 0 | E5: 0
B6: Irrigated Agriculture | C6: 62 | D6: 35 | E6: 48
B7: Livestock (self-supplied) | C7: 0 | D7: 4 | E7: 4
B8: Commercial (self-supplied) | C8: 100 | D8: 95 | E8: 97
B9: Industrial (self-supplied) | C9: 0 | D9: 100 | E9: 100
B10: Mining (self-supplied) | C10: 1 | D10: 63 | E10: 63
B11: Power (self-supplied) | C11: 100 | D11: 100 | E11: 100
B12: Reservoir Evaporation | C12: 76 | D12: 0 | E12: 76
B15: Key: MSW = percent of surface water measured; MGW = percent of groundwater measured; MTW = percent of total withdrawals that were measured.

Sheet 5. CountyWith
B2: Table 5. Summary of withdrawals (acre-feet) in New Mexico counties, 2020.
B3: CN | C3: County | D3: Category | E3: WSW | F3: WGW | G3: TW
B4: 1 | C4: Bernalillo | D4: Public Water Supply | E4: 33249.522 | F4: 68585.502 | G4: 101835.02
B5: 1 | C5: Bernalillo | D5: Domestic (self-supplied) | E5: 0 | F5: 1737.9002 | G5: 1737.9002
B6: 1 | C6: Bernalillo | D6: Irrigated Agriculture | E6: 39564.225 | F6: 2721.6748 | G6: 42285.9
B7: 1 | C7: Bernalillo | D7: Livestock (self-supplied) | E7: 38.456154 | F7: 71.418572 | G7: 109.87473
B8: 1 | C8: Bernalillo | D8: Commercial (self-supplied) | E8: 0 | F8: 6317.1685 | G8: 6317.1685
B9: 1 | C9: Bernalillo | D9: Industrial (self-supplied) | E9: 0 | F9: 2610.38 | G9: 2610.38
B10: 1 | C10: Bernalillo | D10: Mining (self-supplied) | E10: 0 | F10: 339.2856 | G10: 339.2856
B11: 1 | C11: Bernalillo | D11: Power (self-supplied) | E11: 0 | F11: 301.57 | G11: 301.57
B12: 1 | C12: Bernalillo | D12: Reservoir Evaporation | E12: 0 | F12: 0 | G12: 0
D13: County Totals | E13: =SUM(E4:E12) -> 72852.203 | F13: =SUM(F4:F12) -> 82684.9 | G13: =SUM(G4:G12) -> 155537.1
B14: 3 | C14: Catron | D14: Public Water Supply | E14: 0 | F14: 144.53371 | G14: 144.53371
B15: 3 | C15: Catron | D15: Domestic (self-supplied) | E15: 0 | F15: 171.62292 | G15: 171.62292
B16: 3 | C16: Catron | D16: Irrigated Agriculture | E16: 16812.73 | F16: 641.97649 | G16: 17454.707
B17: 3 | C17: Catron | D17: Livestock (self-supplied) | E17: 248.46626 | F17: 106.48554 | G17: 354.9518
B18: 3 | C18: Catron | D18: Commercial (self-supplied) | E18: 2348.71 | F18: 20.079463 | G18: 2368.7895
B19: 3 | C19: Catron | D19: Industrial (self-supplied) | E19: 0 | F19: 0 | G19: 0
B20: 3 | C20: Catron | D20: Mining (self-supplied) | E20: 0 | F20: 0 | G20: 0
B21: 3 | C21: Catron | D21: Power (self-supplied) | E21: 0 | F21: 0 | G21: 0
B22: 3 | C22: Catron | D22: Reservoir Evaporation | E22: 0 | F22: 0 | G22: 0
D23: County Totals | E23: =SUM(E14:E22) -> 19409.906 | F23: =SUM(F14:F22) -> 1084.6981 | G23: =SUM(G14:G22) -> 20494.605
B24: 5 | C24: Chaves | D24: Public Water Supply | E24: 0 | F24: 17160.461 | G24: 17160.461
B25: 5 | C25: Chaves | D25: Domestic (self-supplied) | E25: 0 | F25: 817.13768 | G25: 817.13768
B26: 5 | C26: Chaves | D26: Irrigated Agriculture | E26: 31445.969 | F26: 209688.24 | G26: 241134.21
B27: 5 | C27: Chaves | D27: Livestock (self-supplied) | E27: 224.02939 | F27: 7144.9116 | G27: 7368.941
B28: 5 | C28: Chaves | D28: Commercial (self-supplied) | E28: 2218.9231 | F28: 674.49685 | G28: 2893.4199
B29: 5 | C29: Chaves | D29: Industrial (self-supplied) | E29: 0 | F29: 0 | G29: 0
B30: 5 | C30: Chaves | D30: Mining (self-supplied) | E30: 0 | F30: 24 | G30: 24
B31: 5 | C31: Chaves | D31: Power (self-supplied) | E31: 0 | F31: 0 | G31: 0
B32: 5 | C32: Chaves | D32: Reservoir Evaporation | E32: 0 | F32: 0 | G32: 0
D33: County Totals | E33: =SUM(E24:E32) -> 33888.922 | F33: =SUM(F24:F32) -> 235509.25 | G33: =SUM(G24:G32) -> 269398.17
B34: 6 | C34: Cibola | D34: Public Water Supply | E34: 0 | F34: 2584.7434 | G34: 2584.7434
B35: 6 | C35: Cibola | D35: Domestic (self-supplied) | E35: 0 | F35: 1079.0698 | G35: 1079.0698
B36: 6 | C36: Cibola | D36: Irrigated Agriculture | E36: 2517.2498 | F36: 476.45847 | G36: 2993.7083
B37: 6 | C37: Cibola | D37: Livestock (self-supplied) | E37: 22.280595 | F37: 97.040058 | G37: 119.32065
B38: 6 | C38: Cibola | D38: Commercial (self-supplied) | E38: 0 | F38: 115.96701 | G38: 115.96701
B39: 6 | C39: Cibola | D39: Industrial (self-supplied) | E39: 0 | F39: 392.959 | G39: 392.959
B40: 6 | C40: Cibola | D40: Mining (self-supplied) | E40: 0 | F40: 250.251 | G40: 250.251
B41: 6 | C41: Cibola | D41: Power (self-supplied) | E41: 0 | F41: 0 | G41: 0
...

Sheet 6. RvbWith
B2: Table 6. Summary of withdrawals (acre-feet) in New Mexico river basins, 2020.
B3: RVB | C3: Category | D3: WSW | E3: WGW | F3: TW
B4: AWR | C4: Public Water Supply | D4: 1348.22 | E4: 3577.99 | F4: 4926.21
B5: AWR | C5: Domestic (self-supplied) | D5: 0 | E5: 371.57638 | F5: 371.57638
B6: AWR | C6: Irrigated Agriculture | D6: 164871.15 | E6: 125890.93 | F6: 290762.08
B7: AWR | C7: Livestock (self-supplied) | D7: 1043.2601 | E7: 5568.3171 | F7: 6611.5772
B8: AWR | C8: Commercial (self-supplied) | D8: 462.46025 | E8: 503.06677 | F8: 965.52702
B9: AWR | C9: Industrial (self-supplied) | D9: 0 | E9: 0 | F9: 0
B10: AWR | C10: Mining (self-supplied) | D10: 0 | E10: 37.2 | F10: 37.2
B11: AWR | C11: Power (self-supplied) | D11: 0 | E11: 0 | F11: 0
B12: AWR | C12: Reservoir Evaporation | D12: 70675.101 | E12: 0 | F12: 70675.101
C13: River Basin Totals | D13: =SUM(D4:D12) -> 238400.19 | E13: =SUM(E4:E12) -> 135949.08 | F13: =SUM(F4:F12) -> 374349.27
B14: LC | C14: Public Water Supply | D14: 0 | E14: 3471.8157 | F14: 3471.8157
B15: LC | C15: Domestic (self-supplied) | D15: 0 | E15: 2844.1371 | F15: 2844.1371
B16: LC | C16: Irrigated Agriculture | D16: 54603.277 | E16: 55525.152 | F16: 110128.43
B17: LC | C17: Livestock (self-supplied) | D17: 428.80079 | E17: 540.24172 | F17: 969.04251
B18: LC | C18: Commercial (self-supplied) | D18: 2348.71 | E18: 479.06957 | F18: 2827.7796
B19: LC | C19: Industrial (self-supplied) | D19: 0 | E19: 10.919 | F19: 10.919
B20: LC | C20: Mining (self-supplied) | D20: 0 | E20: 10448.078 | F20: 10448.078
B21: LC | C21: Power (self-supplied) | D21: 0 | E21: 0 | F21: 0
B22: LC | C22: Reservoir Evaporation | D22: 0 | E22: 0 | F22: 0
C23: River Basin Totals | D23: =SUM(D14:D22) -> 57380.788 | E23: =SUM(E14:E22) -> 73319.413 | F23: =SUM(F14:F22) -> 130700.2
B24: P | C24: Public Water Supply | D24: 3141.8399 | E24: 40838.35 | F24: 43980.19
B25: P | C25: Domestic (self-supplied) | D25: 0 | E25: 2431.9957 | F25: 2431.9957
B26: P | C26: Irrigated Agriculture | D26: 196175.04 | E26: 349406.15 | F26: 545581.19
B27: P | C27: Livestock (self-supplied) | D27: 697.73133 | E27: 11019.366 | F27: 11717.098
B28: P | C28: Commercial (self-supplied) | D28: 8078.7931 | E28: 5339.6081 | F28: 13418.401
B29: P | C29: Industrial (self-supplied) | D29: 0 | E29: 2416.194 | F29: 2416.194
B30: P | C30: Mining (self-supplied) | D30: 0 | E30: 38251.784 | F30: 38251.784
B31: P | C31: Power (self-supplied) | D31: 0 | E31: 0 | F31: 0
B32: P | C32: Reservoir Evaporation | D32: 39628.677 | E32: 0 | F32: 39628.677
C33: River Basin Totals | D33: =SUM(D24:D32) -> 247722.08 | E33: =SUM(E24:E32) -> 449703.45 | F33: =SUM(F24:F32) -> 697425.53
B34: RG | C34: Public Water Supply | D34: 44473.437 | E34: 166055.13 | F34: 210528.57
B35: RG | C35: Domestic (self-supplied) | D35: 0 | E35: 20932.954 | F35: 20932.954
B36: RG | C36: Irrigated Agriculture | D36: 720394.23 | E36: 452355.45 | F36: 1172749.7
B37: RG | C37: Livestock (self-supplied) | D37: 692.64626 | E37: 6805.3803 | F37: 7498.0266
B38: RG | C38: Commercial (self-supplied) | D38: 14296.703 | E38: 21038.039 | F38: 35334.742
B39: RG | C39: Industrial (self-supplied) | D39: 0 | E39: 6126.618 | F39: 6126.618
B40: RG | C40: Mining (self-supplied) | D40: 364.67085 | E40: 7553.9147 | F40: 7918.5855
B41: RG | C41: Power (self-supplied) | D41: 0 | E41: 4690.774 | F41: 4690.774
...

Sheet 7. PWS&Dom
B2: Table 7. Public Water Supply and Self-Supplied Domestic in New Mexico counties, 2020. Withdrawals in acre-feet.
B3: CN | C3: RVB | D3: User | E3: POP | F3: GPCD | G3: WEC | H3: WWC | I3: MSW | J3: MGW | K3: WSW | L3: WGW
B4: 1 | C4: RG | D4: ABCWUA | E4: 637707.26 | F4: 137.63259 | G4: 4 | H4: 4 | I4: Y | J4: Y | K4: 33249.522 | L4: 65064.997
B5: 1 | C5: RG | D5: Bakers Mobile Home Park | E5: 160 | F5: 149.60649 | J5: Y | L5: 26.813
B6: 1 | C6: RG | D6: Barcelona Mobile Home Park | E6: 429 | F6: 30.788085 | J6: Y | L6: 14.795
B7: 1 | C7: RG | D7: Bearcat Homeowners Association | E7: 60 | F7: 72.401214 | J7: Y | L7: 4.866
B8: 1 | C8: RG | D8: Cedar Crest MDWC & SWC | E8: 50 | F8: 133.00041 | J8: Y | L8: 7.449
B9: 1 | C9: RG | D9: Chamisa Mobile Home Park | E9: 58 | F9: 66.031976 | J9: Y | L9: 4.29
B10: 1 | C10: RG | D10: Chilili Water Users Assn | E10: 170 | F10: 99.999724 | H10: 1 | L10: 19.042446
B11: 1 | C11: RG | D11: Coronado Village Country Club | E11: 802 | F11: 99.999724 | H11: 1 | L11: 89.835538
B12: 1 | C12: RG | D12: Desert Palms Mobile Home Park | E12: 252 | F12: 110.43761 | J12: Y | L12: 31.174
B13: 1 | C13: RG | D13: Entranosa Water And Wastewater Coop_Bernalillo | E13: 5517.1906 | F13: 172.30565 | G13: 1 | J13: Y | L13: 1064.86
B14: 1 | C14: RG | D14: Forest Park Property Owners Coop | E14: 189 | F14: 46.951511 | H14: 2 | L14: 9.94
B15: 1 | C15: RG | D15: Fox Hills Water Users Assoc | E15: 69 | F15: 99.999724 | H15: 1 | L15: 7.7289927
B16: 1 | C16: RG | D16: Green Acres Mobile Home Village | E16: 200 | F16: 96.723915 | J16: Y | L16: 21.669
B17: 1 | C17: RG | D17: Green Ridge MDWCA, Inc. | E17: 130 | F17: 79.999779 | H17: 1 | L17: 11.649496
B18: 1 | C18: RG | D18: Hamilton Mobile Home Park | E18: 90.8 | F18: 99.999724 | H18: 1 | L18: 10.170906
B19: 1 | C19: RG | D19: Homestead Mobile Home Community | E19: 185 | F19: 41.789883 | J19: Y | L19: 8.66
B20: 1 | C20: RG | D20: Kirtland Air Force Base | E20: 2000 | F20: 159.57281 | G20: 3 | J20: Y | L20: 357.49
B21: 1 | C21: RG | D21: La Mesa Villa Mobile Home Park, LLC | E21: 90 | F21: 99.999724 | H21: 1 | L21: 10.081295
B22: 1 | C22: RG | D22: Leisure Mountain MHP | E22: 172 | F22: 28.624774 | J22: Y | L22: 5.515
B23: 1 | C23: RG | D23: Mountain View Mobile Home Park | E23: 75 | F23: 71.71678 | H23: 5 | L23: 6.025
B24: 1 | C24: RG | D24: North Court Mobile Home Park | E24: 151 | F24: 55.988396 | J24: Y | L24: 9.47
B25: 1 | C25: RG | D25: Oakland Heights Homeowners Association | E25: 30.806203 | F25: 133.27547 | J25: Y | L25: 4.599
B26: 1 | C26: RG | D26: Old Sandia Park Service Co-Op | E26: 200 | F26: 99.999724 | H26: 1 | L26: 22.402877
B27: 1 | C27: RG | D27: Paakweree Village Water Co-Op Assoc, Inc | E27: 178 | F27: 99.999724 | H27: 1 | L27: 19.938561
B28: 1 | C28: RG | D28: Quail Hollow MDWUA | E28: 28 | F28: 99.999724 | H28: 1 | L28: 3.1364028
B29: 1 | C29: RG | D29: Sandia Knolls Water System | E29: 1098 | F29: 99.999724 | H29: 1 | L29: 122.9918
B30: 1 | C30: RG | D30: Sandia Peak Utility | E30: 5727 | F30: 164.24904 | J30: Y | L30: 1053.671
B31: 1 | C31: RG | D31: Sierra Vista Mutual Domestic Association | E31: 342 | F31: 104.84474 | J31: Y | L31: 40.165
B32: 1 | C32: RG | D32: Sierra Vista South Water Coop | E32: 128 | F32: 75.171498 | J32: Y | L32: 10.778
B33: 1 | C33: RG | D33: South Hills Water Company | E33: 506 | F33: 99.999724 | H33: 1 | L33: 56.67928
B34: 1 | C34: RG | D34: Sunset Hills Estates HOA | E34: 76 | F34: 199.99945 | H34: 3 | L34: 17.026187
B35: 1 | C35: RG | D35: The Rincon Water Cooperative | E35: 392 | F35: 114.16596 | J35: Y | L35: 50.13
B36: 1 | C36: RG | D36: Tierra Monte Water Users Association | E36: 78 | F36: 58.234117 | J36: Y | L36: 5.088
B37: 1 | C37: RG | D37: Tierra West Estates MHP | E37: 1730 | F37: 126.37689 | H37: 2 | L37: 244.9
B38: 1 | C38: RG | D38: Tijeras (Village Of) | E38: 541 | F38: 55.412586 | J38: Y | L38: 33.58
B39: 1 | C39: RG | D39: Tijeras Water Cooperative | E39: 155.847 | F39: 116.92054 | J39: Y | L39: 20.411
B40: 1 | C40: RG | D40: Toms Mobile Home Park (aka Shirk MHP) | E40: 39 | F40: 80.804415 | J40: Y | L40: 3.53
B41: 1 | C41: RG | D41: Tranquillo Pines Water Users Coop | E41: 670 | F41: 35.329852 | J41: Y | L41: 26.515
...

Sheet 8. IrrigatedAg
B2: Table 8. Irrigated Agriculture in New Mexico counties, 2020. CIR in feet and withdrawals in acre-feet.
B3: County | C3: RVB | D3: Locale | E3: T | F3: CIR | G3: ASWO | H3: AGWO | I3: ASWC | J3: AGWC | K3: TAI | L3: EF | M3: TFWSW | N3: EC | O3: TPWSW | P3: TPWGW
B4: Bernalillo | C4: RG | D4: MRGCD1 | E4: F | F4: 2.6766233 | G4: 3525.8994 | H4: 0 | I4: 1523.3255 | J4: 507.77515 | K4: 5557 | L4: 0.5 | M4: 27063.845 | N4: 0.68404841 | O4: 39564.225 | P4: 2721.6748
F5: County Totals | G5: 3525.8994 | H5: 0 | I5: 1523.3255 | J5: 507.77515 | K5: 5557 | M5: 27063.845 | O5: 39564.225 | P5: 2721.6748
B6: Catron | C6: LC | D6: Apache/Aragon - SFR | E6: S | F6: 2.0158333 | G6: 0 | H6: 44 | I6: 0 | J6: 0 | K6: 44 | L6: 0.5 | M6: 0 | N6: -- | O6: 0 | P6: 175.82098
B7: Catron | C7: LC | D7: Glenwood - SFR1 | E7: F | F7: 2.5775 | G7: 613 | H7: 0 | I7: 0 | J7: 0 | K7: 613 | L7: 0.55 | M7: 2575.2075 | N7: -- | O7: 10118.473 | P7: 0
B8: Catron | C8: LC | D8: Glenwood - SFR | E8: S | F8: 2.5775 | G8: 0 | H8: 65 | I8: 0 | J8: 0 | K8: 65 | L8: 0.55 | M8: 0 | N8: -- | O8: 0 | P8: 303.53577
B9: Catron | C9: LC | D9: Luna - SFR1 | E9: F | F9: 1.7108333 | G9: 114 | H9: 0 | I9: 0 | J9: 0 | K9: 114 | L9: 0.4 | M9: 415.61276 | N9: -- | O9: 1942.2745 | P9: 0
B10: Catron | C10: LC | D10: Reserve - SFR1 | E10: F | F10: 2.0266667 | G10: 260 | H10: 0 | I10: 0 | J10: 0 | K10: 260 | L10: 0.5 | M10: 665.95271 | N10: -- | O10: 4751.983 | P10: 0
B11: Catron | C11: LC | D11: Reserve - SFR | E11: S | F11: 2.0266667 | G11: 0 | H11: 40 | I11: 0 | J11: 0 | K11: 40 | L11: 0.5 | M11: 0 | N11: -- | O11: 0 | P11: 162.61973
F12: County Totals | G12: 987 | H12: 149 | I12: 0 | J12: 0 | K12: 1136 | M12: 3656.773 | O12: 16812.73 | P12: 641.97649
B13: Chaves | C13: P | D13: RAB and Pecos Pumpers1 | E13: F | F13: 3.1916667 | G13: 123.95404 | H13: 4757.6849 | I13: 314.94444 | J13: 472.41667 | K13: 5669 | L13: 0.6 | M13: 2334.6961 | N13: 0.75 | O13: 3112.9281 | P13: 24316
B14: Chaves | C14: P | D14: RAB and Pecos Pumpers1 | E14: S | F14: 2.8695728 | G14: 1223.3601 | H14: 46955.807 | I14: 3108.3333 | J14: 4662.5 | K14: 55950 | L14: 0.7 | M14: 17757.3 | N14: 0.75 | O14: 23676.399 | P14: 184941
B15: Chaves | C15: P | D15: Rio Hondo | E15: F | F15: 2.6583333 | G15: 377 | H15: 0 | I15: 0 | J15: 0 | K15: 377 | L15: 0.55 | M15: 1822.1667 | N15: 0.7 | O15: 2603.0952 | P15: 0
B16: Chaves | C16: P | D16: Rio Peñasco | E16: F | F16: 2.855 | G16: 11.076923 | H16: 16.615385 | I16: 265.84615 | J16: 66.461538 | K16: 360 | L16: 0.55 | M16: 1437.4825 | N16: 0.7 | O16: 2053.5465 | P16: 431.24476
F17: County Totals | G17: 1735.3911 | H17: 51730.107 | I17: 3689.1239 | J17: 5201.3782 | K17: 62356 | M17: 23351.645 | O17: 31445.969 | P17: 209688.24
B18: Cibola | C18: RG | D18: Rio San Jose | E18: F | F18: 1.8883333 | G18: 384.81957 | H18: 83.743119 | I18: 128.40612 | J18: 55.031193 | K18: 652 | L18: 0.55 | M18: 1762.0749 | N18: 0.7 | O18: 2517.2498 | P18: 476.45847
F19: County Totals | G19: 384.81957 | H19: 83.743119 | I19: 128.40612 | J19: 55.031193 | K19: 652 | M19: 1762.0749 | O19: 2517.2498 | P19: 476.45847
B20: Colfax | C20: AWR | D20: Canadian River | E20: F | F20: 1.6249867 | G20: 3830 | H20: 0 | I20: 0 | J20: 0 | K20: 3830 | L20: 0.55 | M20: 11315.816 | N20: 0.6 | O20: 18859.694 | P20: 0
B21: Colfax | C21: AWR | D21: Canadian River | E21: S | F21: 1.54 | G21: 100 | H21: 0 | I21: 0 | J21: 0 | K21: 100 | L21: 0.65 | M21: 236.92308 | N21: 0.6 | O21: 394.87179 | P21: 0
B22: Colfax | C22: AWR | D22: Capulin | E22: F | F22: 1.35 | G22: 0 | H22: 50 | I22: 0 | J22: 0 | K22: 50 | L22: 0.55 | M22: 0 | N22: -- | O22: 0 | P22: 122.72727
B23: Colfax | C23: AWR | D23: Cimarron River1 | E23: F | F23: 1.68902 | G23: 5220 | H23: 0 | I23: 0 | J23: 0 | K23: 5220 | L23: 0.55 | M23: 6222.7328 | N23: 0.6 | O23: 10371.221 | P23: 0
B24: Colfax | C24: AWR | D24: Cimarron River1 | E24: S | F24: 1.3167033 | G24: 2740 | H24: 0 | I24: 0 | J24: 0 | K24: 2740 | L24: 0.65 | M24: 2158.7272 | N24: 0.6 | O24: 3597.8787 | P24: 0
B25: Colfax | C25: AWR | D25: Dry Cimarron River | E25: F | F25: 1.9733333 | G25: 595 | H25: 0 | I25: 0 | J25: 0 | K25: 595 | L25: 0.55 | M25: 2134.7879 | N25: 0.7 | O25: 3049.697 | P25: 0
B26: Colfax | C26: AWR | D26: Dry Cimarron River | E26: S | F26: 1.7697208 | G26: 0 | H26: 496 | I26: 0 | J26: 0 | K26: 496 | L26: 0.55 | M26: 0 | N26: -- | O26: 0 | P26: 1595.9664
B27: Colfax | C27: AWR | D27: Vermejo CD | E27: F | F27: 1.57986 | G27: 4090 | H27: 0 | I27: 0 | J27: 0 | K27: 4090 | L27: 0.55 | M27: 11748.413 | N27: 0.84 | O27: 13986.206 | P27: 0
B28: Colfax | C28: AWR | D28: Vermejo CD | E28: S | F28: 1.54 | G28: 1100 | H28: 0 | I28: 0 | J28: 0 | K28: 1100 | L28: 0.55 | M28: 3080 | N28: 0.84 | O28: 3666.6667 | P28: 0
F29: County Totals | G29: 17675 | H29: 546 | I29: 0 | J29: 0 | K29: 18221 | M29: 36897.401 | O29: 53926.236 | P29: 1718.6937
B30: Curry | C30: AWR | D30: AWR Basin Scattered | E30: S | F30: 1.259961 | G30: 0 | H30: 4375 | I30: 0 | J30: 0 | K30: 4375 | L30: 0.75 | M30: 0 | N30: -- | O30: 0 | P30: 7349.7722
B31: Curry | C31: P | D31: Pecos Basin Scattered | E31: S | F31: 1.3879444 | G31: 0 | H31: 960 | I31: 0 | J31: 0 | K31: 960 | L31: 0.75 | M31: 0 | N31: -- | O31: 0 | P31: 1776.5689
B32: Curry | C32: TG | D32: Texas Gulf Basin Scattered | E32: F | F32: 2.3233333 | G32: 0 | H32: 81 | I32: 0 | J32: 0 | K32: 81 | L32: 0.65 | M32: 0 | N32: -- | O32: 0 | P32: 289.52308
B33: Curry | C33: TG | D33: Texas Gulf Basin Scattered | E33: S | F33: 1.2112992 | G33: 0 | H33: 110751 | I33: 0 | J33: 0 | K33: 110751 | L33: 0.75 | M33: 0 | N33: -- | O33: 0 | P33: 178870.13
F34: County Totals | G34: 0 | H34: 116167 | I34: 0 | J34: 0 | K34: 116167 | M34: 0 | O34: 0 | P34: 188285.99
B35: De Baca | C35: P | D35: Ft. Sumner ID1 | E35: F | F35: 2.6234671 | G35: 5773 | H35: 0 | I35: 0 | J35: 0 | K35: 5773 | L35: 0.55 | M35: 27536.865 | N35: 0.7 | O35: 42542 | P35: 0
B36: De Baca | C36: P | D36: Pecos Basin Scattered | E36: S | F36: 2.0062787 | G36: 0 | H36: 3351 | I36: 0 | J36: 0 | K36: 3351 | L36: 0.65 | M36: 0 | N36: -- | O36: 0 | P36: 10343.138
F37: County Totals | G37: 5773 | H37: 3351 | I37: 0 | J37: 0 | K37: 9124 | M37: 27536.865 | O37: 42542 | P37: 10343.138
B38: Dona Ana | C38: RG | D38: Hueco GW Basin | E38: D | F38: 3.5979982 | G38: 0 | H38: 186 | I38: 0 | J38: 0 | K38: 186 | L38: 0.85 | M38: 0 | N38: -- | O38: 0 | P38: 787.32666
B39: Dona Ana | C39: RG | D39: Inside EBID1 | E39: F | F39: 2.8499316 | G39: 960 | H39: 0 | I39: 19874.785 | J39: 49691.215 | K39: 70526 | L39: 0.6 | M39: 88424.602 | N39: 0.46187433 | O39: 191447.32 | P39: 210893.75
B40: Dona Ana | C40: RG | D40: Nutt-Hockett | E40: F | F40: 3.7873928 | G40: 0 | H40: 246 | I40: 0 | J40: 0 | K40: 246 | L40: 0.6 | M40: 0 | N40: -- | O40: 0 | P40: 1552.8311
B41: Dona Ana | C41: RG | D41: Outside EBID | E41: F | F41: 1.5704367 | G41: 0 | H41: 197 | I41: 0 | J41: 0 | K41: 197 | L41: 0.6 | M41: 0 | N41: -- | O41: 0 | P41: 515.62672
...

Sheet 9. AcresCounty
B2: Table 9. Acres irrigated by water source and by irrigation method, withdrawals by water source in acre-feet, in New Mexico counties, 2020.
B3: County | C3: ASWO | D3: AGWO | E3: ACW | F3: TDA | G3: TFA | H3: TSA | I3: TAI | J3: TPWSW | K3: TPWGW | L3: TPW
B4: Bernalillo | C4: 3525.8994 | D4: 0 | E4: 2031.1006 | F4: 0 | G4: 5557 | H4: 0 | I4: 5557 | J4: 39564.225 | K4: 2721.6748 | L4: 42285.9
B5: Catron | C5: 987 | D5: 149 | E5: 0 | F5: 0 | G5: 987 | H5: 149 | I5: 1136 | J5: 16812.73 | K5: 641.97649 | L5: 17454.707
B6: Chaves | C6: 1735.3911 | D6: 51730.107 | E6: 8890.5021 | F6: 0 | G6: 6406 | H6: 55950 | I6: 62356 | J6: 31445.969 | K6: 209688.24 | L6: 241134.21
B7: Cibola | C7: 384.81957 | D7: 83.743119 | E7: 183.43731 | F7: 0 | G7: 652 | H7: 0 | I7: 652 | J7: 2517.2498 | K7: 476.45847 | L7: 2993.7083
B8: Colfax | C8: 17675 | D8: 546 | E8: 0 | F8: 0 | G8: 13785 | H8: 4436 | I8: 18221 | J8: 53926.236 | K8: 1718.6937 | L8: 55644.929
B9: Curry | C9: 0 | D9: 116167 | E9: 0 | F9: 0 | G9: 81 | H9: 116086 | I9: 116167 | J9: 0 | K9: 188285.99 | L9: 188285.99
B10: De Baca | C10: 5773 | D10: 3351 | E10: 0 | F10: 0 | G10: 5773 | H10: 3351 | I10: 9124 | J10: 42542 | K10: 10343.138 | L10: 52885.138
B11: Dona Ana | C11: 960 | D11: 1522 | E11: 69566 | F11: 186 | G11: 70969 | H11: 893 | I11: 72048 | J11: 191447.32 | K11: 218660.19 | L11: 410107.51
B12: Eddy | C12: 2142.3446 | D12: 23222 | E12: 11051.655 | F12: 0 | G12: 29712 | H12: 6704 | I12: 36416 | J12: 69613.898 | K12: 115027.97 | L12: 184641.87
B13: Grant | C13: 1858.8 | D13: 984.55 | E13: 139.65 | F13: 0 | G13: 2351 | H13: 632 | I13: 2983 | J13: 28878.063 | K13: 4540.2312 | L13: 33418.294
B14: Guadalupe | C14: 2339 | D14: 0 | E14: 0 | F14: 0 | G14: 2300 | H14: 39 | I14: 2339 | J14: 20649.267 | K14: 0 | L14: 20649.267
B15: Harding | C15: 0 | D15: 2469 | E15: 0 | F15: 0 | G15: 0 | H15: 2469 | I15: 2469 | J15: 0 | K15: 5502.578 | L15: 5502.578
... B37: State | C37: 212177.23 | D37: 454953.96 | E37: 119060.81 | F37: 16533 | G37: 275052 | H37: 494607 | I37: 786192 | J37: 1467441.6 | K37: 1499255.5 | L37: 2966697.2
B40: Key: ASWO = acres irrigated with surface water only; AGWO = acres irrigated with groundwater only; ACW = acres irrigated with combined surface water and groundwater; TDA = total drip irrigated acres; TFA = total flood irrigated acres; TSA = total sprinkler irrigated acres; TAI = total acres irrigated; TPWSW = total project withdrawal, surface water; TPWGW = total project withdrawal, groundwater; TPW = total project withdrawal.

Sheet 10. AcresRvb
B2: Table 10. Acres irrigated by water source and by irrigation method, withdrawals by water source in acre-feet, in New Mexico river basins, 2020.
B3: RVB | C3: ASWO | D3: AGWO | E3: ACW | F3: TDA | G3: TFA | H3: TSA | I3: TAI | J3: TPWSW | K3: TPWGW | L3: TPW
B4: AWR | C4: 39364 | D4: 60487 | E4: 0 | F4: 0 | G4: 30830 | H4: 69021 | I4: 99851 | J4: 164871.15 | K4: 125890.93 | L4: 290762.08
B5: LC | C5: 4375 | D5: 10539 | E5: 0 | F5: 315 | G5: 8096 | H5: 6503 | I5: 14914 | J5: 54603.277 | K5: 55525.152 | L5: 110128.43
B6: P | C6: 16645.592 | D6: 83447.386 | E6: 20777.021 | F6: 0 | G6: 49317 | H6: 71553 | I6: 120870 | J6: 196175.04 | K6: 349406.15 | L6: 545581.19
B7: RG | C7: 67160.636 | D7: 65109.576 | E7: 98283.789 | F7: 15952 | G7: 174724 | H7: 39878 | I7: 230554 | J7: 720394.23 | K7: 452355.45 | L7: 1172749.7
B8: TG | C8: 0 | D8: 235371 | E8: 0 | F8: 0 | G8: 81 | H8: 235290 | I8: 235371 | J8: 0 | K8: 516077.87 | L8: 516077.87
B9: UC | C9: 84632 | D9: 0 | E9: 0 | F9: 266 | G9: 12004 | H9: 72362 | I9: 84632 | J9: 331397.94 | K9: 0 | L9: 331397.94
B10: State | C10: 212177.23 | D10: 454953.96 | E10: 119060.81 | F10: 16533 | G10: 275052 | H10: 494607 | I10: 786192 | J10: 1467441.6 | K10: 1499255.5 | L10: 2966697.2
B13: Key: RVB = river basin; ASWO = acres irrigated with surface water only; AGWO = acres irrigated with groundwater only; ACW = acres irrigated with combined surface water and groundwater; TDA = total drip irrigated acres; TFA = total flood irrigated acres; TSA = total sprinkler irrigated acres; TAI = total acres irrigated; TPWSW = total project withdrawal, surface water; TPWGW = total project withdrawal, groundwater; TPW = total project withdrawal.

Sheet Livestock populations
B2: Livestock Populations by County | K2: Livestock Populations by River Basin
B3: County | C3: Non-Dairy Cattle | D3: Dairy Cattle | E3: Horses | F3: Sheep/Lambs | G3: Hogs/Pigs | H3: Chickens | K3: Basin | L3: Non-Dairy Cattle | M3: Dairy Cattle | N3: Horses | O3: Sheep/Lambs | P3: Hogs/Pigs | Q3: Chickens
B4: Bernalillo | C4: 3406 | D4: 664 | E4: 1282 | F4: 1381 | G4: 129 | H4: 9729.536 | K4: Arkansas-White-Red Basin | L4: 412056.64 | M4: 26447.6 | N4: 4134.04 | O4: 3674.07 | P4: 101.08 | Q4: 7879.3628
B5: Catron | C5: 30119 | D5: 0 | E5: 1149 | F5: 303 | G5: 9 | H5: 738.36303 | K5: Lower Colorado Basin | L5: 81361.18 | M5: 100.97 | N5: 3093.38 | O5: 1706.81 | P5: 191.1 | Q5: 4824.252
B6: Chaves | C6: 100000 | D6: 85000 | E6: 1052 | F6: 18000 | G6: 40 | H6: 1905 | K6: Pecos Basin | L6: 243770.71 | M6: 115486.87 | N6: 5773.04 | O6: 25665.56 | P6: 526.78 | Q6: 12156.647
B7: Cibola | C7: 9869 | D7: 1 | E7: 477 | F7: 450 | G7: 120 | H7: 2704 | K7: Rio Grande Basin | L7: 206785.06 | M7: 68158.86 | N7: 11763.11 | O7: 16879.29 | P7: 699.15 | Q7: 43242.827
B8: Colfax | C8: 59799 | D8: 62 | E8: 864 | F8: 657 | G8: 37 | H8: 1031.892 | K8: Texas Gulf Basin | L8: 184698.11 | M8: 128650 | N8: 860.73 | O8: 2033.07 | P8: 16.49 | Q8: 69172.072
B9: Curry | C9: 90724 | D9: 85000 | E9: 64 | F9: 17 | G9: 0 | H9: 3983 | K9: Upper Colorado Basin | L9: 19601.3 | M9: 49.7 | N9: 1774.7 | O9: 5347.2 | P9: 68.4 | Q9: 9418.6
B10: De Baca | C10: 27200 | D10: 3 | E10: 274 | F10: 621 | G10: 23 | H10: 397.94362 | L10: 1148273 | M10: 338894 | N10: 27399 | O10: 55306 | P10: 1603 | Q10: 146693.76
B11: Dona Ana | C11: 60000 | D11: 33000 | E11: 1565 | F11: 1798 | G11: 55 | H11: 4908
B12: Eddy | C12: 21838 | D12: 13000 | E12: 2000 | F12: 1035 | G12: 300 | H12: 2500
B13: Grant | C13: 24380 | D13: 13 | E13: 1229 | F13: 350 | G13: 21 | H13: 764.12371
B14: Guadalupe | C14: 26452 | D14: 0 | E14: 334 | F14: 1892 | G14: 0 | H14: 477
B15: Harding | C15: 30999 | D15: 0 | E15: 300 | F15: 64 | G15: 0 | H15: 84.526955
B16: Hidalgo | C16: 26757 | D16: 10 | E16: 705 | F16: 245 | G16: 106 | H16: 245
B17: Lea | C17: 58830 | D17: 32000 | E17: 593 | F17: 1648 | G17: 0 | H17: 1494
B18: Lincoln | C18: 29464 | D18: 5 | E18: 1308 | F18: 3598 | G18: 32 | H18: 1513.204 | L18: Withdrawals by Livestock Category in acre-feet
B19: Los Alamos | C19: 0 | D19: 0 | E19: 0 | F19: 0 | G19: 0 | H19: 0 | L19: Category | M19: WSW | N19: WGW | O19: TW
B20: Luna | C20: 19000 | D20: 10856 | E20: 600 | F20: 200 | G20: 100 | H20: 647.74964 | L20: Non-Dairy Cattle | M20: 2824.6124 | N20: 10037.733 | O20: 12862.345
B21: McKinley | C21: 7097 | D21: 0 | E21: 148 | F21: 1053 | G21: 4 | H21: 2334 | L21: Dairy Cattle | M21: 272.88869 | N21: 24829.618 | O21: 25102.506
B22: Mora | C22: 25000 | D22: 30 | E22: 1898 | F22: 1454 | G22: 15 | H22: 3000 | L22: Horses | M22: 19.377429 | N22: 379.60436 | O22: 398.98179
B23: Otero | C23: 16500 | D23: 18 | E23: 1500 | F23: 400 | G23: 60 | H23: 1811 | L23: Sheep/Lambs | M23: 29.621579 | N23: 106.67029 | O23: 136.29187
B24: Quay | C24: 41245 | D24: 0 | E24: 635 | F24: 1000 | G24: 7 | H24: 1269.3022 | L24: Hogs/Pigs | M24: 0.29222797 | N24: 5.0945588 | O24: 5.3867867
B25: Rio Arriba | C25: 26713 | D25: 149 | E25: 895 | F25: 7032 | G25: 32 | H25: 6892 | L25: Chickens | M25: 0.42577109 | N25: 12.719715 | O25: 13.145486
B26: Roosevelt | C26: 92291 | D26: 55000 | E26: 477 | F26: 1065 | G26: 17 | H26: 67677.208 | M26: 3147.2181 | N26: 35371.439 | O26: 38518.657
B27: Sandoval | C27: 7000 | D27: 0 | E27: 906 | F27: 1000 | G27: 0 | H27: 2762
B28: San Juan | C28: 9468 | D28: 5 | E28: 1386 | F28: 2927 | G28: 58 | H28: 6608
B29: San Miguel | C29: 2250 | D29: 14 | E29: 50 | F29: 636 | G29: 108 | H29: 2899 | L29: Key: WSW = withdrawal surface water; WGW = withdrawal groundwater; TW = total withdrawal.
B30: Santa Fe | C30: 7098 | D30: 70 | E30: 1004 | F30: 530 | G30: 0 | H30: 3951.4501
B31: Sierra | C31: 20000 | D31: 2060 | E31: 601 | F31: 169 | G31: 75 | H31: 1969
B32: Socorro | C32: 3541 | D32: 12000 | E32: 650 | F32: 450 | G32: 23 | H32: 1081.4613
B33: Taos | C33: 5853 | D33: 30 | E33: 954 | F33: 1684 | G33: 43 | H33: 3344
B34: Torrance | C34: 29658 | D34: 1404 | E34: 669 | F34: 2412 | G34: 143 | H34: 1283
B35: Union | C35: 227298 | D35: 0 | E35: 432 | F35: 21 | G35: 0 | H35: 207
B36: Valencia | C36: 8424 | D36: 8500 | E36: 1398 | F36: 1214 | G36: 46 | H36: 6482
C37: 1148273 | D37: 338894 | E37: 27399 | F37: 55306 | G37: 1603 | H37: 146693.76

Sheet Livestock withdrawals
A1: Livestock. Withdrawals in acre-feet, in New Mexico Counties, 2020.
A2: County | B2: RVB | C2: User | D2: Pop | E2: GPCD | F2: WSW | G2: WGW | H2: Total
A3: Bernalillo | B3: Rio Grande Basin | C3: Non-Dairy Cattle | D3: 3406 | E3: 10 | F3: 13.353272 | G3: 24.798934 | H3: 38.152206
A4: Bernalillo | B4: Rio Grande Basin | C4: Dairy Cattle | D4: 664 | E4: 65 | F4: 16.92094 | G4: 31.424603 | H4: 48.345543
A5: Bernalillo | B5: Rio Grande Basin | C5: Horses | D5: 1282 | E5: 13 | F5: 6.5339293 | G5: 12.13444 | H5: 18.668369 | K5: Key: RVB = river basin; POP = population; GPCD = gallons per capita per day; WSW = withdrawal, surface water; WGW = withdrawal, groundwater; Total = total withdrawal.
A6: Bernalillo | B6: Rio Grande Basin | C6: Sheep/Lambs | D6: 1381 | E6: 2.2 | F6: 1.1911307 | G6: 2.2120998 | H6: 3.4032305
A7: Bernalillo | B7: Rio Grande Basin | C7: Hogs/Pigs | D7: 129 | E7: 3 | F7: 0.15172391 | G7: 0.28177297 | H7: 0.43349687
A8: Bernalillo | B8: Rio Grande Basin | C8: Chickens | D8: 9729.536 | E8: 0.08 | F8: 0.30515828 | G8: 0.56672253 | H8: 0.87188081
A9: Bernalillo Total | F9: =SUBTOTAL(9,F3:F8) -> 38.456154 | G9: =SUBTOTAL(9,G3:G8) -> 71.418572 | H9: =SUBTOTAL(9,H3:H8) -> 109.87473
A10: Catron | B10: Lower Colorado Basin | C10: Non-Dairy Cattle | D10: 30119 | E10: 10 | F10: 236.16394 | G10: 101.21312 | H10: 337.37706
A11: Catron | B11: Lower Colorado Basin | C11: Dairy Cattle | D11: 0 | E11: 65 | F11: 0 | G11: 0 | H11: 0
A12: Catron | B12: Lower Colorado Basin | C12: Horses | D12: 1149 | E12: 13 | F12: 11.712145 | G12: 5.0194906 | H12: 16.731635
A13: Catron | B13: Lower Colorado Basin | C13: Sheep/Lambs | D13: 303 | E13: 2.2 | F13: 0.52268298 | G13: 0.22400699 | H13: 0.74668997
A14: Catron | B14: Lower Colorado Basin | C14: Hogs/Pigs | D14: 9 | E14: 3 | F14: 0.021170778 | G14: 0.0090731904 | H14: 0.030243968
A15: Catron | B15: Lower Colorado Basin | C15: Chickens | D15: 738.36303 | E15: 0.08 | F15: 0.046316206 | G15: 0.019849802 | H15: 0.066166008
A16: Catron | B16: Rio Grande Basin | C16: Non-Dairy Cattle | D16: 0 | E16: 10 | F16: 0 | G16: 0 | H16: 0
A17: Catron | B17: Rio Grande Basin | C17: Dairy Cattle | D17: 0 | E17: 65 | F17: 0 | G17: 0 | H17: 0
A18: Catron | B18: Rio Grande Basin | C18: Horses | D18: 0 | E18: 13 | F18: 0 | G18: 0 | H18: 0
A19: Catron | B19: Rio Grande Basin | C19: Sheep/Lambs | D19: 0 | E19: 2.2 | F19: 0 | G19: 0 | H19: 0
A20: Catron | B20: Rio Grande Basin | C20: Hogs/Pigs | D20: 0 | E20: 3 | F20: 0 | G20: 0 | H20: 0
A21: Catron | B21: Rio Grande Basin | C21: Chickens | D21: 0 | E21: 0.08 | F21: 0 | G21: 0 | H21: 0
A22: Catron Total | F22: =SUBTOTAL(9,F10:F21) -> 248.46626 | G22: =SUBTOTAL(9,G10:G21) -> 106.48554 | H22: =SUBTOTAL(9,H10:H21) -> 354.9518
A23: Chaves | B23: Pecos Basin | C23: Non-Dairy Cattle | D23: 100000 | E23: 10 | F23: 224.02939 | G23: 896.11757 | H23: 1120.147
A24: Chaves | B24: Pecos Basin | C24: Dairy Cattle | D24: 85000 | E24: 65 | F24: 0 | G24: 6188.812 | H24: 6188.812
A25: Chaves | B25: Pecos Basin | C25: Horses | D25: 1052 | E25: 13 | F25: 0 | G25: 15.31913 | H25: 15.31913
A26: Chaves | B26: Pecos Basin | C26: Sheep/Lambs | D26: 18000 | E26: 2.2 | F26: 0 | G26: 44.35782 | H26: 44.35782
A27: Chaves | B27: Pecos Basin | C27: Hogs/Pigs | D27: 40 | E27: 3 | F27: 0 | G27: 0.13441764 | H27: 0.13441764
A28: Chaves | B28: Pecos Basin | C28: Chickens | D28: 1905 | E28: 0.08 | F28: 0 | G28: 0.1707104 | H28: 0.1707104
A29: Chaves | B29: Rio Grande Basin | C29: Non-Dairy Cattle | D29: 0 | E29: 10 | F29: 0 | G29: 0 | H29: 0
A30: Chaves | B30: Rio Grande Basin | C30: Dairy Cattle | D30: 0 | E30: 65 | F30: 0 | G30: 0 | H30: 0
A31: Chaves | B31: Rio Grande Basin | C31: Horses | D31: 0 | E31: 13 | F31: 0 | G31: 0 | H31: 0
A32: Chaves | B32: Rio Grande Basin | C32: Sheep/Lambs | D32: 0 | E32: 2.2 | F32: 0 | G32: 0 | H32: 0
A33: Chaves | B33: Rio Grande Basin | C33: Hogs/Pigs | D33: 0 | E33: 3 | F33: 0 | G33: 0 | H33: 0
A34: Chaves | B34: Rio Grande Basin | C34: Chickens | D34: 0 | E34: 0.08 | F34: 0 | G34: 0 | H34: 0
... A40: Chaves | B40: Texas Gulf Basin | C40: Chickens | D40: 0 | E40: 0.08 | F40: 0 | G40: 0 | H40: 0
A41: Chaves Total | F41: =SUBTOTAL(9,F23:F40) -> 224.02939 | G41: =SUBTOTAL(9,G23:G40) -> 7144.9116 | H41: =SUBTOTAL(9,H23:H40) -> 7368.941
A42: Cibola | B42: Lower Colorado Basin | C42: Non-Dairy Cattle | D42: 6612.23 | E42: 10 | F42: 14.813339 | G42: 59.253355 | H42: 74.066694
A43: Cibola | B43: Lower Colorado Basin | C43: Dairy Cattle | D43: 0.67 | E43: 65 | F43: 0.003902592 | G43: 0.044879808 | H43: 0.0487824
A44: Cibola | B44: Lower Colorado Basin | C44: Horses | D44: 319.59 | E44: 13 | F44: 0 | G44: 4.653841 | H44: 4.653841
A45: Cibola | B45: Lower Colorado Basin | C45: Sheep/Lambs | D45: 301.5 | E45: 2.2 | F45: 0.059439478 | G45: 0.683554 | H45: 0.74299348
...

Sheet Power
B2: 2020 Power Generating Facilities
B3: File Number | C3: Name Of Water User | D3: County Number | E3: Groundwater Basin | F3: River Basin | G3: TWN | H3: RNG | I3: SEC | J3: Energy Generated | K3: WSW | L3: WGW | M3: Comments
J4: Megawatt Hours | K4: Acre-feet | L4: Acre-feet
C5: PNM--Rio Bravo (AKA Delta-Person) | D5: 1 | E5: RG | F5: RG | G5: 10N | H5: 03E | I5: 7 | J5: 125197 | K5: 0 | L5: 4.54
B6: RG-50 | C6: PNM--Reeves | D6: 1 | E6: RG | F6: RG | J6: 110415 | K6: 0 | L6: 297.03
B8: LRG 11409 | C8: Afton Generating Station (PNM) | D8: 13 | E8: LRG | F8: RG | J8: 903364 | K8: 0 | L8: 249.22
B9: LRG-780, 779, 780 | C9: El Paso Electric--Rio Grande | D9: 13 | E9: LRG | F9: RG | G9: 29S | H9: 03E | I9: 1 | K9: 0 | L9: 1596.813
C11: Lordsburg Generating Station (PNM) | D11: 23 | F11: RG | J11: 12046 | K11: 0 | L11: 16.23
C12: Tri State-Plains Electric--Pyramid | D12: 23 | F12: RG | J12: 129490 | K12: 0 | L12: 43.4
C14: Hobbs Generating Station | D14: 25 | E14: LEA | F14: TG | K14: 0 | L14: 249.03
B15: L-1726 & 1731 | C15: Lea County Co-Op | D15: 25 | E15: LEA | F15: TG | G15: 15S | H15: 35E | I15: 0 | J15: 29381 | K15: 0 | L15: 24960
B16: L-5834 & 1550 | C16: Xcel Energy--Cunningham | D16: 25 | E16: LEA | F16: TG | G16: 17S | H16: 35E | I16: 0 | K16: 0 | L16: 1577.46
B17: L-5176 & 3117 | C17: Xcel Energy--Maddox | D17: 25 | E17: LEA | F17: TG | G17: 18S | H17: 36E | I17: 25 | K17: 0 | L17: 1468.59
C19: Luna Energy Facility | D19: 29 | F19: RG | J19: 404335 | K19: 0 | L19: 254.72
B21: B-18,19,43-49,7,6,87 | C21: Tri-State-Plains Electric--Escalante | D21: 31 | E21: BLU | F21: RG | I21: 0 | J21: 641360 | K21: 0 | L21: 2226.631
C23: PNM--Blackwater Station | D23: 41 | E23: POR | F23: TG | G23: 01N | H23: 36E | I23: 21 | K23: 0 | L23: 0
C25: Bluffview Power Plant | D25: 45 | F25: UC | K25: 0 | L25: 0 | M25: 389 af supplied by public water supplier
C26: Animas Power Plant | D26: 45 | F26: UC | K26: 0 | L26: 0 | M26: all af supplied by public water supplier
B27: 2838 & 3258 | C27: PNM--San Juan Generating Station--Waterflow | D27: 45 | F27: UC | J27: 3092725 | K27: 12096.81 | L27: 0
C28: Four Corners Power Plant (BHP) | D28: 45 | F28: UC | J28: 952995 | K28: 20377.18 | L28: 0
C30: PNM La Luz Energy Center | D30: 61 | F30: RG | J30: 19484 | K30: 0 | L30: 2.19
C31: Valencia Energy Facility (operated by Southwest Generation) | D31: 61 | F31: RG | J31: 71785 | K31: 0 | L31: 0 | M31: 2 af supplied by public water supplier
C33: State Total | K33: =SUM(K5:K31) -> 32473.99 | L33: =SUM(L5:L31) -> 32945.854
B36: Key: WSW = withdrawal surface water; WGW = withdrawal groundwater.

Sheet Reservoirs
B2: 2020 Reservoir Net Evaporation in acre-feet (for reservoirs with a storage capacity of 5,000 acre-feet or more)
B3: Reservoir | C3: County | D3: RVB | E3: Net Evaporation
B4: Navajo Reservoir | C4: San Juan | D4: UC | E4: 26095
B5: Elephant Butte Reservoir | C5: Sierra | D5: RG | E5: 79669.194
B6: Caballo Reservoir | C6: Sierra | D6: RG | E6: 29665.743
B7: Abiquiu Reservoir | C7: Rio Arriba | D7: RG | E7: 12094
B8: Cochiti Lake | C8: Sandoval | D8: RG | E8: 5554
B9: Conchas Lake | C9: San Miguel | D9: AWR | E9: 24200
B10: Jemez Canyon Reservoir | C10: Sandoval | D10: RG | E10: 3
B11: Santa Rosa Reservoir | C11: Guadalupe | D11: P | E11: 7011
B12: Brantley Lake | C12: Eddy | D12: P | E12: 17135.382
B13: Heron Reservoir | C13: Rio Arriba | D13: RG | E13: 8980.58
B14: El Vado Reservoir | C14: Rio Arriba | D14: RG | E14: 4815.88
B15: Farmington Lake | C15: San Juan | D15: UC | E15: 1078.6535
... B29: Stubblefield Reservoir | C29: Colfax | D29: AWR | E29: 852.77917
E30: 282522.09

Sheet CropTypes
B2: Crop Types and Acres used in Blaney-Criddle evapotranspiration calculations, 2020.
B3: Crop | C3: Bernalillo | D3: Catron | E3: Chaves | F3: Cibola | G3: Colfax | H3: Curry | I3: De Baca | J3: Dona Ana | K3: Eddy | L3: Grant | M3: Guadalupe | N3: Harding | O3: Hidalgo | P3: Lea | Q3: Lincoln | R3: Luna | S3: McKinley | T3: Mora | U3: Otero | V3: Quay | W3: Rio Arriba | X3: Roosevelt | Y3: Sandoval | Z3: San Juan | AA3: San Miguel | AB3: Santa Fe | AC3: Sierra | AD3: Socorro | AE3: Taos | AF3: Torrance | AG3: Union | AH3: Valencia | AI3: State
B4: Corn (Grain) | C4: 0 | D4: 0 | E4: 0 | F4: 2 | G4: 0 | H4: 5070 | I4: 0 | J4: 0 | K4: 0 | L4: 5 | M4: 0 | N4: 30 | O4: 0 | P4: 248 | Q4: 0 | R4: 236 | S4: 0 | T4: 0 | U4: 0 | V4: 0 | W4: 0 | X4: 2300 | Y4: 0 | Z4: 20563.364 | AA4: 0 | AB4: 0 | AC4: 0 | AD4: 0 | AE4: 0 | AF4: 0 | AG4: 13938.817 | AH4: 0 | AI4: 42393.181
B5: Corn (Silage) | C5: 61.239286 | D5: 0 | E5: 20824 | F5: 0 | G5: 0 | H5: 19100 | I5: 118 | J5: 0 | K5: 4281 | L5: 7 | M5: 0 | N5: 0 | O5: 4374 | P5: 8163 | Q5: 0 | R5: 1314 | S5: 0 | T5: 0 | U5: 0 | V5: 1509 | W5: 0 | X5: 11004 | Y5: 34.305215 | Z5: 739.79371 | AA5: 0 | AB5: 4168 | AC5: 177 | AD5: 1570.3384 | AE5: 0 | AF5: 5895 | AG5: 0 | AH5: 1186.9988 | AI5: 84526.675
B6: Sorghum (Grain) | C6: 0 | D6: 0 | E6: 348 | F6: 0 | G6: 0 | H6: 2868 | I6: 70 | J6: 107 | K6: 0 | L6: 0 | M6: 0 | N6: 1831.4429 | O6: 0 | P6: 627 | Q6: 0 | R6: 670 | S6: 0 | T6: 0 | U6: 0 | V6: 0 | W6: 0 | X6: 1200 | Y6: 0 | Z6: 21.635933 | AA6: 0 | AB6: 0 | AC6: 38 | AD6: 0 | AE6: 0 | AF6: 0 | AG6: 4082.6451 | AH6: 0 | AI6: 11863.724
B7: Sorghum (Silage) | C7: 0 | D7: 0 | E7: 2906 | F7: 0 | G7: 290 | H7: 12733 | I7: 661 | J7: 7817 | K7: 356 | L7: 7 | M7: 52 | N7: 0 | O7: 20 | P7: 1308 | Q7: 0 | R7: 189 | S7: 0 | T7: 0 | U7: 0 | V7: 4800 | W7: 0 | X7: 6125 | Y7: 0 | Z7: 1758.9337 | AA7: 0 | AB7: 0 | AC7: 638 | AD7: 0 | AE7: 0 | AF7: 233 | AG7: 1150 | AH7: 0 | AI7: 41043.934
B8: Barley (Wnt Pln) | C8: 0 | D8: 0 | E8: 5767 | F8: 0 | G8: 0 | H8: 84 | I8: 0 | J8: 31 | K8: 1819 | L8: 0 | M8: 0 | N8: 0 | O8: 0 | P8: 1375 | Q8: 0 | R8: 33 | S8: 0 | T8: 0 | U8: 13 | V8: 0 | W8: 0 | X8: 760 | Y8: 0 | Z8: 0 | AA8: 0 | AB8: 0 | AC8: 28 | AD8: 0 | AE8: 0 | AF8: 108 | AG8: 0 | AH8: 0 | AI8: 10018
B9: Rye (Wnt Pln) | C9: 0 | D9: 0 | E9: 0 | F9: 8 | G9: 0 | H9: 176 | I9: 0 | J9: 0 | K9: 176 | L9: 0 | M9: 0 | N9: 0 | O9: 0 | P9: 4560 | Q9: 0 | R9: 77 | S9: 0 | T9: 0 | U9: 0 | V9: 123 | W9: 0 | X9: 0 | Y9: 0 | Z9: 0 | AA9: 0 | AB9: 0 | AC9: 0 | AD9: 0 | AE9: 0 | AF9: 0 | AG9: 1424.8614 | AH9: 0 | AI9: 6544.8614
B10: Wheat (Wnt Pln) | C10: 0 | D10: 0 | E10: 17664 | F10: 81 | G10: 635 | H10: 69030 | I10: 1865 | J10: 1707 | K10: 2947 | L10: 0 | M10: 39 | N10: 42.2711 | O10: 2379 | P10: 14889 | Q10: 2 | R10: 3299 | S10: 0 | T10: 414 | U10: 36 | V10: 10230 | W10: 3 | X10: 23303 | Y10: 0 | Z10: 6898.1 | AA10: 722 | AB10: 187 | AC10: 249 | AD10: 0 | AE10: 0 | AF10: 1557 | AG10: 25051.531 | AH10: 0 | AI10: 183229.9
B11: Wheat (Spr Pln) | C11: 0 | D11: 0 | E11: 0 | F11: 0 | G11: 0 | H11: 0 | I11: 0 | J11: 0 | K11: 0 | L11: 0 | M11: 0 | N11: 0 | O11: 0 | P11: 0 | Q11: 0 | R11: 416 | S11: 0 | T11: 0 | U11: 0 | V11: 0 | W11: 0 | X11: 0 | Y11: 0 | Z11: 0 | AA11: 0 | AB11: 0 | AC11: 0 | AD11: 0 | AE11: 0 | AF11: 0 | AG11: 0 | AH11: 0 | AI11: 416
B12: Misc spr small grains | C12: 2.9936917 | D12: 44 | E12: 537 | F12: 0 | G12: 260 | H12: 3985 | I12: 0 | J12: 211 | K12: 327 | L12: 14 | M12: 0 | N12: 0 | O12: 174 | P12: 1769 | Q12: 0 | R12: 130 | S12: 0 | T12: 162 | U12: 474 | V12: 460 | W12: 0 | X12: 1600 | Y12: 7.1270245 | Z12: 410.04082 | AA12: 0 | AB12: 210 | AC12: 125 | AD12: 143.47956 | AE12: 0 | AF12: 0 | AG12: 418.1187 | AH12: 267.03484 | AI12: 11730.795
B13: Cotton (Upland/Pima) | C13: 0 | D13: 0 | E13: 420 | F13: 0 | G13: 0 | H13: 1594 | I13: 0 | J13: 8609 | K13: 3356 | L13: 0 | M13: 0 | N13: 283.86208 | O13: 640 | P13: 19076 | Q13: 0 | R13: 4609 | S13: 0 | T13: 0 | U13: 254 | V13: 800 | W13: 1 | X13: 1450 | Y13: 0 | Z13: 0 | AA13: 0 | AB13: 0 | AC13: 256 | AD13: 0 | AE13: 0 | AF13: 0 | AG13: 477 | AH13: 0 | AI13: 41825.862
B14: Sugar beets | C14: 0 | D14: 0 | E14: 0 | F14: 0 | G14: 0 | H14: 0 | I14: 0 | J14: 0 | K14: 0 | L14: 0 | M14: 0 | N14: 0 | O14: 0 | P14: 0 | Q14: 0 | R14: 0 | S14: 0 | T14: 0 | U14: 0 | V14: 0 | W14: 0 | X14: 0 | Y14: 0 | Z14: 0 | AA14: 0 | AB14: 0 | AC14: 0 | AD14: 0 | AE14: 0 | AF14: 0 | AG14: 0 | AH14: 0 | AI14: 0
B15: Misc field crops | C15: 0 | D15: 0 | E15: 0 | F15: 0 | G15: 0 | H15: 0 | I15: 0 | J15: 333 | K15: 39 | L15: 0 | M15: 0 | N15: 0 | O15: 0 | P15: 0 | Q15: 0 | R15: 67 | S15: 0 | T15: 0 | U15: 0 | V15: 0 | W15: 0 | X15: 0 | Y15: 0 | Z15: 9.8601094 | AA15: 0 | AB15: 0 | AC15: 0 | AD15: 0 | AE15: 0 | AF15: 0 | AG15: 253.07323 | AH15: 0 | AI15: 701.93334
... B38: Net Irrigated | C38: 5556.9376 | D38: 1136 | E38: 62356 | F38: 652 | G38: 18221 | H38: 116167 | I38: 9124 | J38: 72048 | K38: 36416 | L38: 2983 | M38: 2339 | N38: 2468.5959 | O38: 16602 | P38: 69425 | Q38: 2104 | R38: 27396 | S38: 66 | T38: 9356 | U38: 4654 | V38: 20221 | W38: 23612 | X38: 55699 | Y38: 6845.9993 | Z38: 84374.473 | AA38: 6555 | AB38: 8798 | AC38: 4687 | AD38: 17886.228 | AE38: 16021 | AF38: 17114 | AG38: 45266.683 | AH38: 20041.08 | AI38: 786192
